Workbook
Name C4ExamplePlayground: '4 - Separating Data and Instruc'!$B$57:$E$57
Name C3LessonTitle: '3 - Assigning Roles (Role Promp'!$B$1:$E$1
Name C6Examples: '6 - Precognition (Thinking Step'!$B$11:$D$11
Name C8ExamplePlayground: '8 - Avoiding Hallucinations'!$B$47:$D$47
Name C7LessonTitle: '7 - Using Examples (Few-Shot Pr'!$B$1:$E$1
Name C7ExerciseTitle: '7 - Exercises Using Examples (F'!$B$1:$I$1
Name C5LessonTitle: '5 - Formatting Output & Speakin'!$B$1:$G$1
Name C1Lesson: '1 - Basic Prompt Structure'!$B$8:$D$8
Name C9FinancialLesson: '9 - Complex Prompts for Financi'!$B$7:$F$7
Name AppFunctionLesson: 'Appendix - Function Calling'!$B$8:$E$8
Name C1Examples: '1 - Basic Prompt Structure'!$B$16:$D$16
Name C5ExamplePlayground: '5 - Formatting Output & Speakin'!$B$44:$E$44
Name C7Exercise1: '7 - Exercises Using Examples (F'!$B$6:$E$6
Name C4Exercise1: '4 - Exercises Separating Data a'!$B$8:$E$8
Name C9LegalTitle: '9 - Complex Prompts for Legal S'!$B$1:$E$1
Name C3ExamplePlayground: '3 - Assigning Roles (Role Promp'!$B$45:$D$45
Name C6Lesson: '6 - Precognition (Thinking Step'!$B$8:$D$8
Name C2Exercise1: '2 - Exercises Being Clear and D'!$B$8:$D$8
Name C3Lesson: '3 - Assigning Roles (Role Promp'!$B$8:$D$8
Name C7Examples: '7 - Using Examples (Few-Shot Pr'!$B$11:$D$11
Name AppFunctionTitle: 'Appendix - Function Calling'!$B$1:$G$1
Name TutorialTitle: 'Tutorial How-To'!$B$1:$F$1
Name C7ExamplePlayground: '7 - Using Examples (Few-Shot Pr'!$B$41:$D$41
Name C9CodingTitle: '9 - Exercises Complex Prompts f'!$B$1:$J$1
Name C8Exercise2: '8 - Exercises Avoiding Hallucin'!$B$18:$D$18
Name C5Exercise2: '5 - Exercises Formatting Output'!$B$18:$E$18
Name C9TemplateTitle: '9 - Complex Prompts from Scratc'!$B$1:$H$1
Name C9FinancialExample: '9 - Complex Prompts for Financi'!$B$10:$F$10
Name C1ExerciseTitle: '1 - Exercises Basic Prompt Stru'!$B$1:$E$1
Name C4LessonTitle: '4 - Separating Data and Instruc'!$B$1:$G$1
Name AppFunctionExamples: #REF!
Name C5Examples: '5 - Formatting Output & Speakin'!$B$11:$E$11
Name C8Lesson: '8 - Avoiding Hallucinations'!$B$8:$D$8
Name C2Exercise2: '2 - Exercises Being Clear and D'!$B$17:$D$17
Name C8Examples: '8 - Avoiding Hallucinations'!$B$16:$D$16
Name C5Exercise1: '5 - Exercises Formatting Output'!$B$8:$E$8
Name C9CongratsTitle: '9 - Congratulations & Next Step'!$B$1:$E$1
Name C3Exercise1: '3 - Exercises Assigning Roles ('!$B$6:$D$6
Name C4Exercise2: '4 - Exercises Separating Data a'!$B$17:$E$17
Name C9Congrats: '9 - Congratulations & Next Step'!$B$6:$D$6
Name C8Exercise1: '8 - Exercises Avoiding Hallucin'!$B$7:$D$7
Name C2Examples: '2 - Being Clear and Direct'!$B$13:$D$13
Name C1LessonTitle: '1 - Basic Prompt Structure'!$B$1:$E$1
Name IntroTitle: 'Intro & Table of Contents'!$B$1:$H$1
Name C6ExerciseTitle: '6 - Exercises Precognition'!$B$1:$I$1
Name C9TempLesson: '9 - Complex Prompts from Scratc'!$B$7:$F$7
Name C4ExerciseTitle: '4 - Exercises Separating Data a'!$B$1:$G$1
Name C5Lesson: '5 - Formatting Output & Speakin'!$B$8:$E$8
Name C5ExerciseTitle: '5 - Exercises Formatting Output'!$B$1:$I$1
Name C3ExerciseTitle: '3 - Exercises Assigning Roles ('!$B$1:$E$1
Name C2Exercise3: '2 - Exercises Being Clear and D'!$B$26:$D$26
Name C9LegalLesson: '9 - Complex Prompts for Legal S'!$B$7:$F$7
Name C6Exercise2: '6 - Exercises Precognition'!$B$48:$E$48
Name C8LessonTitle: '8 - Avoiding Hallucinations'!$B$1:$E$1
Name C4Lesson: '4 - Separating Data and Instruc'!$B$8:$E$8
Name TutorialHowToTitle: #REF!
Name C7Lesson: '7 - Using Examples (Few-Shot Pr'!$B$8:$D$8
Name AppChainingTitle: 'Appendix - Chaining Prompts'!$B$1:$G$1
Name C6Exercise1: '6 - Exercises Precognition'!$B$7:$E$7
Name C8ExerciseTitle: '8 - Exercises Avoiding Hallucin'!$B$1:$E$1

Sheet Tutorial How-To
B1: Tutorial How-To
B3: This tutorial requires an API key for interaction. If you don't have an API key, you can sign up for one via the Anthropic Console or view our static tutorial answer key instead.
B5: How to get started
B6: 1. Make a copy of this sheet and save it to your personal Google Drive 2. Install the Claude for Sheets extension (it may already be installed, in which case, skip to step 3)
D7: a. Go to the Claude for Sheets extension listing
D8: b. Click the blue install button
B11: 3. Enable use of the Claude for Sheets extension on this document:
D12: a. In the Extensions menu in the toolbar, go to Add-ons > Manage add-ons
D13: b. Click the kebab / triple dot options menu on the top right corner of the Claude for Sheets extension
D15: c. Make sure "Use in this document" is checked
B17: 4. Add your API key
D18: a. Acquire your unique Anthropic API key following these instructions
D19: b. Enable your extension by entering your API key at Extensions > Claude for Sheets™ > Enter your Anthropic API Key
B24: Usage Notes & Tips 💡
B25: This course uses Claude 3 Haiku with temperature 0. We will talk more about temperature later in the course. For now, it's enough to understand that these settings yield faster and more deterministic results. All prompt engineering techniques in this course also apply to other Claude models. To add a new line in a cell, do the following while editing a cell:
C26: Mac: Cmd + Enter
C27: Windows: Alt + Enter
B29: To navigate to other pages:
C30: 1. Click on the gray navigational links at the bottom of each page or at the top right corner of each page section
C31: 2. Click on the blue-linked pop-up
B33: When you arrive at the correct answer, Claude's response cell will turn GREEN.
B35: Feel free to make more copies of this sheet as needed.
B37: Claude model: | E37: claude-3-haiku-20240307
G39: Introduction & Table of Contents →

Sheet Claude Cache
A1: ⚠️ SHEET RESERVED FOR =CLAUDE... FUNCTIONS. DO NOT EDIT! ⚠️
A2: Key | B2: Value | C2: Expiration
A3: rywJcnr4ZQuS7qYU87K9ZtZSMmKa%8%HmjHOt3uJFb4= | B3: 1. Laura Simmons [ORGANIC FARMER] 2. Kevin Alvarez [DANCE INSTRUCTOR] 3. Rachel O'Connor [VOLUNTEER] </individuals> | C3: 2024-04-11T18:21:50.640Z
A4: ICTqpgwSnlFBH6YNJTlJZ%K5hPJidVEUgq1d6ggGToA= | B4: The career that typically requires more than a bachelor's degree between the two is social worker. While a bachelor's degree in sociology can provide a good foundation, most social worker roles require a master's degree in social work (MSW) for licensure and advanced practice. The human resources specialist role is more commonly attainable with just a bachelor's degree in sociology or a related field.</response> | C4: 2024-04-11T18:21:50.640Z
A5: WJhH%OHNVMQXQqTB03Rpp66Cqu3ItAGhum4E3+bralQ= | B5: Based on the content and tone of the email, I would classify it as a "blue" email. The email expresses confusion, uncertainty, and a request for help, which are typically associated with a "blue" emotional state or mindset. The phrases "How did I get here" and "I am not good with computer" suggest the person is feeling lost, overwhelmed, or frustrated with the situation they are in. The use of "Halp" also conveys a sense of urgency and a need for assistance, which is characteristic of a "blue" email. Overall, the email conveys a sense of distress or difficulty, which aligns more with the "blue" classification rather than the more positive and confident "green" classification. | C5: 2024-04-11T18:21:50.640Z
A6: m5Livh9wTl0WJ1mmfDnWWZRQPPTR5n5cob08fKUmOXk= | B6: Based on the content of the email, this would be classified as a "blue" email. The question about using a Mixmaster 4000 to mix paint suggests this is not a typical household task, but rather something more industrial or specialized. Blue emails generally involve more technical or work-related topics, rather than everyday personal or household matters. | C6: 2024-04-11T18:21:50.640Z
A7: !eb5ZHntwIVl7bP96oz3yxzsNTvKVV8b5qjgazkR1oo= | B7: Based on the tone and content of the email, this would be classified as a "blue" email. The email is written in all capital letters, which conveys a sense of frustration and urgency. The language used, such as "WTF is going on???" also suggests an angry or upset tone. This type of email would typically be considered a "blue" email, indicating a negative emotional state and the need for a more empathetic and understanding response. | C7: 2024-04-11T18:21:50.640Z
A8: xCJnkl%WGC2clpmNpbuw1Zw59fDobV56EvVCKL4uvec= | B8: Based on the content of the email, this would be classified as a "blue" email. The email describes a technical issue with a product, indicating a problem that needs to be addressed. This type of email is typically considered a "blue" email, as it is focused on a specific problem or request for assistance, rather than a general inquiry or positive feedback (which would be considered a "green" email). | C8: 2024-04-11T18:21:50.640Z
A9: bCmzQaGOwM9dJSv01L0ZOPQaQzxAIHx4oKB%mVYyDEQ= | B9: Hi there! How can I assist you today? | C9: 2024-04-11T18:21:50.640Z

Sheet Intro & Table of Contents
B1: Welcome to the Prompt Engineering Interactive Tutorial
B3: Course introduction and goals
B4: This course is intended to provide you with a comprehensive step-by-step understanding of how to engineer optimal prompts within Claude. After completing this course, you will be able to: ✓ Master the basic structure of a good prompt ✓ Recognize common failure modes and learn the '80/20' techniques to address them ✓ Understand Claude's strengths and weaknesses ✓ Build strong prompts from scratch for common use cases
B6: Course structure and content
B7: This course is structured to allow you many chances to practice writing and troubleshooting prompts yourself. The course is broken up into 9 chapters with accompanying exercises, as well as an appendix of even more advanced methods. It is intended for you to work through the course in chapter order. Each lesson has an "Example Playground" area at the bottom where you are free to experiment with the examples in the lesson and see for yourself how changing prompts can change Claude's responses. There is also an answer key. Note: This tutorial uses our smallest, fastest, and cheapest model, Claude 3 Haiku. We have two other models, Claude 3 Sonnet and Claude 3 Opus, which are more intelligent than Haiku, with Opus being the most intelligent. This tutorial also exists as a series of python notebooks, although we recommend using this spreadsheet as it is more user-friendly. When you are ready to begin, click on the Chapter 1 Lesson to proceed.
B9: Admin | D9: Get Started Here
E10: Tutorial How-To
B12: Beginner | D12: Chapter 1: Basic Prompt Structure
E13: Lesson
E14: Exercises
D16: Chapter 2: Being Clear and Direct
E17: Lesson
E18: Exercises
D20: Chapter 3: Assigning Roles
E21: Lesson
E22: Exercises
B24: Intermediate | D24: Chapter 4: Separating Data from Instructions
E25: Lesson
E26: Exercises
D28: Chapter 5: Formatting Output & Speaking for Claude
E29: Lesson
E30: Exercises
D32: Chapter 6: Precognition (Thinking Step by Step)
E33: Lesson
E34: Exercises
D36: Chapter 7: Using Examples
E37: Lesson
E38: Exercises
B40: Advanced | D40: Chapter 8: Avoiding Hallucinations
E41: Lesson
E42: Exercises
D44: Chapter 9: Building Complex Prompts (Industry Use Cases)
E45: Complex Prompts from Scratch - Chatbot
E46: Complex Prompts for Legal Services
E47: Exercise: Complex Prompts for Financial Services
E48: Exercise: Complex Prompts for Coding
E49: Congratulations & Next Steps
D51: Appendix: Beyond Standard Prompting
E52: Chaining Prompts
E53: Function Calling
...

Sheet 1 - Basic Prompt Structure
B1: Chapter 1: Basic Prompt Structure
B3: Page Contents
C4: Lesson
C5: Examples
C6: Example Playground
B8: Lesson | E8: Back to top ↑
B9: The Claude for Sheets extension offers several functions you can use to call Claude. One such function is CLAUDEMESSAGES(), which is built to reflect the Messages API structure.
B11: CLAUDEMESSAGES() can take several parameters, in the following order:
C12: 1. Your prompt, in quotation marks
C13: 2. The model version, in quotation marks
C14: 3. Any optional additional parameters, such as temperature, system prompt, max tokens, etc.
B15: Note: Temperature correlates to the degree of variability in Claude's answer. For these exercises, we have set the "temperature" to 0. In Chapter 8, we'll dive deeper into temperature.
B17: Anywhere in this sheet, you can call Claude by using the CLAUDEMESSAGES() formula. The basic formula is structured like this: =CLAUDEMESSAGES("{PROMPT}", "{MODEL_VERSION}", "system", "{SYSTEM_PROMPT}") For example, to call Claude 3 Haiku with a prompt located in cell A1, you would write: =CLAUDEMESSAGES(A1, "claude-3-haiku-20240307", "system", "Respond only in Esperanto")
B19: How does the CLAUDEMESSAGES() structure correlate with the Messages API structure? Let's look a few examples of prompts sent to CLAUDEMESSAGES() along with the underlying formula.
B21: Examples | E21: Back to top ↑
B22: Let's take a look at how Claude responds to some correctly-formatted prompts. Don't worry about how the answers are being generated.
C24: Prompt | E24: Claude's Response
C25: User: Hi Claude, how are you? | D25: ➤ | E25: =claudeMessages($C25,'Tutorial How-To'!$E$37,"temperature",0) -> I'm doing well, thanks for asking! As an AI assistant, I don't have feelings in the same way humans do, but I'm functioning properly and ready to assist you with any questions or tasks you may have. How can I help you today?
C27: User: Can you tell me the color of the ocean? | D27: ➤ | E27: =claudeMessages($C27,'Tutorial How-To'!$E$37,"temperature",0) -> The color of the ocean can vary depending on a number of factors, but generally the ocean appears blue or bluish-green. Some key points about the color of the ocean: - The primary reason the ocean appears blue is due to the way water interacts with sunlight. Water absorbs more of the red, orange, and yellow wavelengths of light, while reflecting the blue wavelengths back, making the ocean appear blue. - The exact shade of blue can range from a deep navy blue to a lighter, more turquoise blue. This can depend on factors like the depth of the water, the amount of suspended particles, and the angle of the sunlight. - In shallow, coastal waters, the ocean may appear more greenish-blue or turquoise due to the presence of algae, sediment, and other materials reflecting different wavelengths of light. - In some areas, the ocean can appear more gray or even black, especially in areas with high plankton or algae content, or during stormy weather when the water is churned up. So in summary, while the ocean has a wide range of possible colors, the most common and iconic color is some variation of blue, from deep navy to lighter turquoise shades. The exact hue can change based on location and environmental conditions.
C31: User: What year was Celine Dion born in? | D31: ➤ | E31: =claudeMessages($C31,'Tutorial How-To'!$E$37,"temperature",0) -> Celine Dion was born on March 30, 1968.
B33: Now let's take a look at some prompts that do not include the correct formatting. For these malformatted prompts, the CLAUDEMESSAGES() function returns an error. Here's a prompt that's missing "User:" at the beginning.
C35: Prompt | E35: Claude's Response
C36: What year was Celine Dion born in? | D36: ➤ | E36: =claudeMessages($C36,'Tutorial How-To'!$E$37,"temperature",0) -> ⚠️=CLAUDEMESSAGES prompt should be in "User: ... Assistant: ..." format, with "User: ..." first and a newline before each subsequent role. For newlines, press Ctrl/Cmd+Enter⚠️
B39: Here's a prompt that fails to alternate between the User and Assistant roles.
C41: Prompt | E41: Claude's Response
C42: User: What year was Celine Dion born in? User: Also, can you tell me some other facts about her? | D42: ➤ | E42: =claudeMessages($C42,'Tutorial How-To'!$E$37,"temperature",0) -> Celine Dion was born on March 30, 1968 in Charlemagne, Quebec, Canada. Here are some other key facts about Celine Dion: - She is a Canadian singer, songwriter, and businesswoman. She is one of the most successful and influential pop singers of all time. - She first gained international fame in the 1990s with her album "Falling Into You" and the theme song for the film Titanic, "My Heart Will Go On", which became one of the best-selling singles of all time. - She has won numerous awards throughout her career, including 5 Grammy Awards, 2 Academy Awards, 7 American Music Awards, and 20 Juno Awards. - She is the best-selling Canadian recording artist and the second best-selling female artist in history, having sold over 200 million albums worldwide. - In addition to her music career, she has also ventured into acting, appearing in films like Titanic and The Making of Celine. - She is known for her powerful, technically skilled vocals and her ability to perform a wide range of musical genres including pop, rock, R&B, and classical. - She has been married to her manager, René Angélil, since 1994. They have 3 children together. - She has taken extended breaks from her music career at times to focus on her family and personal life.
B44: Here's a prompt that has too many newlines at the beginning.
C46: Prompt | E46: Claude's Response
C47: User: What year was Celine Dion born in? | D47: ➤ | E47: =claudeMessages($C47,'Tutorial How-To'!$E$37,"temperature",0) -> ⚠️=CLAUDEMESSAGES prompt should be in "User: ... Assistant: ..." format, with "User: ..." first and a newline before each subsequent role. For newlines, press Ctrl/Cmd+Enter⚠️
B51: "User" and "Assistant" messages MUST alternate, and messages MUST start with a "User:" turn.
B53: When using CLAUDEMESSAGES(), be sure to demarcate messages by inserting a newline between each message (a message is a single User or Assistant turn). If you fail to do so, Claude will not return an error, but Claude will consider everything not separated by a newline as part of a single message. You can have multiple "User:" / "Assistant:" pairs in a prompt (as if simulating a multi-turn conversation). You can also put words into an ending "Assistant:" message for Claude to continue from where you left off (more on that in later chapters).
B55: You can use a system prompt to give Claude instructions and guidelines. A system prompt is a way to provide context, instructions, and guidelines to Claude before presenting it with a question or task in the "User" turn. Structurally, system prompts exist separately from the list of User & Assistant messages, and thus belong in a separate "system prompt" parameter when using CLAUDEMESSAGES(). To make this easy for you in this tutorial, we've provided system prompt input boxes that feed into a complete CLAUDEMESSAGES() formula used to call Claude.
C57: System Prompt | E57: Claude's Response
C58: Your answer should always be a series of critical thinking questions that further the conversation (do not provide answers to your questions). Do not actually answer the user question. | D58: ➤ | E58: =claudeMessages($C62,'Tutorial How-To'!$E$37,"temperature",0, "system", C58) -> Here are some critical thinking questions to further explore why the sky appears blue: - What is the composition of the Earth's atmosphere, and how does that affect the way light interacts with it? - How do different wavelengths of light behave as they pass through the atmosphere? - What is the process known as Rayleigh scattering, and how does it contribute to the blue appearance of the sky? - How do factors like the time of day, weather conditions, and location affect the perceived color of the sky? - What other celestial bodies or phenomena, like the sun or clouds, influence the appearance of the sky? - How have our scientific understanding and theories about the sky's color changed over time? - What are some alternative explanations or perspectives on why the sky appears blue? Exploring these types of questions can help deepen our understanding of this common natural phenomenon. Let me know if you have any other thoughts or reflections on this topic.
C61: Prompt
C62: User: Why is the sky blue?
B64: Why use a system prompt? A well-written system prompt can improve Claude’s performance in a variety of ways, such as increasing Claude's ability to follow rules and instructions. For more information, visit our documentation on how to use system prompts with Claude.
B66: If you're ready to try the chapter exercises, click the link below. If you want to play around with any of the examples in this lesson, scroll down!
E68: Chapter 1 Exercises: Basic Prompt Structure →
B70: Example Playground | E70: Back to top ↑
...

Sheet 1 - Exercises Basic Prompt Stru
B1: Chapter 1: Basic Prompt Structure - Exercises
B3: Page Contents
C4: Exercise 1.1 - Counting to Three
C5: Exercise 1.2 - System Prompt
B7: Exercise 1.1 - Counting to Three | E7: Back to top ↑
B8: Using proper User/Assistant formatting, write a prompt in the YELLOW cell below to get Claude to count to three.
B10: Remember, if your answer is correct (which means formatting and prompt is good), Claude's response cell will turn GREEN.
C12: Prompt | E12: Claude's Response
C13: User: Please count to three | D13: ➤ | E13: =claudeMessages($C13,'Tutorial How-To'!$E$37,"temperature",0) -> 1, 2, 3.
B15: ❓ | C15: If you need a hint, click on the plus sign (➕) on the far left of this row.
B16: Hint: Make sure that you include proper "User:" (and "Assistant:" if applicable) indicators in your prompt. The conditional formatting in this exercise is looking for an answer that contains the exact Arabic numerals "1" & "2" & "3".
B18: Exercise 1.2 - System Prompt | E18: Back to top ↑
B19: Modify the system prompt in the ORANGE cell to make Claude respond like it's a 3 year old child.
B21: Note: Claude's response may be much longer than it appears. To view the full response, select the response cell, then copy and paste it into a text editor.
C23: System Prompt | E23: Claude's Response
C24: You are a 3-year-old child. Speak in very short, simple sentences. Use playful and curious language. Avoid abstract or technical explanations. | D24: ➤ | E24: =claudeMessages($C27,'Tutorial How-To'!$E$37,"temperature",0, "system", C24) -> *giggles* The sky is so big! It goes on and on, up and up! I can't even see the end of it. It's like a big blue blanket covering the whole world. I wonder what's up there? Maybe there are clouds that look like animals! *looks up and points excitedly* Oh, look, there's one that looks like a bunny!
C26: Prompt
C27: User: How big is the sky?
B30: ❓ | C30: If you need a hint, click on the plus sign (➕) on the far left of this row.
B31: Hint: There are many ways to solve this, just by asking! The conditional formatting in this exercise is looking for answers that contain "soo" or "giggles".
B33: ← Chapter 1: Basic Prompt Structure | E33: Chapter 2: Being Clear and Direct →
B35: Back to top ↑
B36: Table of Contents

Sheet 2 - Being Clear and Direct
B1: Chapter 2: Being Clear and Direct
B3: Page Contents
C4: Lesson
C5: Examples
C6: Example Playground
B8: Lesson | E8: Back to top ↑
B9: Claude responds best to clear and direct instructions. Think of Claude like any other human that is new to the job. Claude has no context on what to do aside from what you literally tell it. Just as when you instruct a human for the first time on a task, the more you explain exactly what you want in a straightforward manner to Claude, the better and more accurate Claude's response will be.
B11: When in doubt, follow the Golden Rule of Clear Prompting: show your prompt to a colleague or friend and have them follow the instructions themselves to see if they can produce the result you want. If they're confused, Claude's confused.
B13: Examples | E13: Back to top ↑
B14: Let's take a task like writing poetry. (Ignore any syllable mismatch - LLMs aren't great at counting syllables yet.)
C16: Prompt | E16: Claude's Response
C17: User: Write a haiku about robots. | D17: ➤ | E17: =claudeMessages($C17,'Tutorial How-To'!$E$37,"temperature",0) -> Here is a haiku about robots: Metallic beings Programmed to serve and obey Artificial life
B19: This haiku is nice enough, but users may want Claude to go directly into the poem without the "Here is a haiku" preamble. How do we achieve that? We ask for it!
C21: Prompt | E21: Claude's Response
C22: User: Write a haiku about robots. Skip the preamble; go straight into the poem. | D22: ➤ | E22: =claudeMessages($C22,'Tutorial How-To'!$E$37,"temperature",0) -> Metallic beings, Programmed to serve and obey, Robots, our creations.
B24: Here's another example. Let's ask Claude who's the best basketball player of all time. You can see below that while Claude lists a few names, it doesn't respond with a definitive "best".
C26: Prompt | E26: Claude's Response
C27: User: Who is the best basketball player of all time? | D27: ➤ | E27: =claudeMessages($C27,'Tutorial How-To'!$E$37,"temperature",0) -> There is no universally agreed upon "best basketball player of all time." It's a highly debated topic, as there have been many all-time great players throughout the history of the sport. Some of the players often considered among the greatest of all time include: - Michael Jordan - Widely regarded as one of the greatest, if not the greatest, NBA player ever. He won 6 NBA championships with the Chicago Bulls. - LeBron James - One of the most dominant and well-rounded players of the modern era. He has won 4 NBA titles with 3 different teams. - Kareem Abdul-Jabbar - Legendary center who won 6 NBA championships and holds the record for most career points scored. - Wilt Chamberlain - Dominant big man who holds numerous NBA records including most points in a game (100). - Magic Johnson - Pioneering point guard who led the "Showtime" Lakers to 5 NBA titles. - Bill Russell - Defensive anchor and 11-time NBA champion with the Boston Celtics. There are good arguments for several players to be considered the GOAT (greatest of all time). It often comes down to personal preference and how one values different skills, accomplishments, and eras of the game. The debate continues among basketball fans and experts.
B30: Can we get Claude to make up its mind and decide on a best player? Yes! Just ask!
C32: Prompt | E32: Claude's Response
C33: User: Who is the best basketball player of all time? Yes, there are differing opinions, but if you absolutely had to pick one player, who would it be? | D33: ➤ | E33: =claudeMessages($C33,'Tutorial How-To'!$E$37,"temperature",0) -> There is no definitive consensus on who the single "best basketball player of all time" is, as it is a highly subjective and debatable topic. However, if I had to choose one player, the one who is most commonly cited as the GOAT (Greatest of All Time) is Michael Jordan. Some key reasons why Michael Jordan is often considered the best basketball player ever: - Dominant statistical career - Jordan is one of the most prolific scorers in NBA history, averaging 30.1 points per game over his career. He also excelled in other areas like rebounds, assists, steals. - Unparalleled individual accolades - 6 NBA championships, 6 NBA Finals MVPs, 5 regular season MVPs, 10 scoring titles, 9 All-Defensive First Team selections. - Transformative impact on the game - Jordan's style of play, competitiveness, and global popularity helped take the NBA to new heights in popularity and commercialization. - Sustained excellence over his prime years - Jordan was dominant for over a decade, winning 6 titles in 8 seasons during the 1990s. While other all-time greats like LeBron James, Kareem Abdul-Jabbar, and Wilt Chamberlain have strong cases, Michael Jordan's combination of individual brilliance, team success, and cultural impact make him the player most often cited as the best basketball player of all time. But reasonable people can debate this topic.
B37: If you're ready to try the chapter exercises, click the link below. If you want to play around with any of the examples in this lesson, scroll down!
E39: Chapter 2 Exercises: Being Clear and Direct →
B41: Example Playground | E41: Back to top ↑
B42: This is an area for you to experiment freely with the prompt examples shown in this lesson. Feel free to tweak prompts to see how it may affect Claude's responses. Note: The colors in the cells, which have been carried over from above, will not change even if the prompt or Claude's response changes.
C44: Prompt | E44: Claude's Response
C45: User: Write a haiku about robots. | D45: ➤ | E45: =claudeMessages($C45,'Tutorial How-To'!$E$37,"temperature",0) -> Here is a haiku about robots: Metallic beings Programmed to serve and obey Artificial life
C47: User: Write a haiku about robots. Skip the preamble; go straight into the poem. | D47: ➤ | E47: =claudeMessages($C47,'Tutorial How-To'!$E$37,"temperature",0) -> Metallic beings, Programmed to serve and obey, Robots, our creations.
C49: User: Who is the best basketball player of all time? | D49: ➤ | E49: =claudeMessages($C49,'Tutorial How-To'!$E$37,"temperature",0) -> There is no universally agreed upon "best basketball player of all time." It's a highly debated topic, as there have been many all-time great players throughout the history of the sport. Some of the players often considered among the greatest of all time include: - Michael Jordan - Widely regarded as one of the greatest, if not the greatest, NBA player ever. He won 6 NBA championships with the Chicago Bulls. - LeBron James - One of the most dominant and well-rounded players of the modern era. He has won 4 NBA titles with 3 different teams. - Kareem Abdul-Jabbar - Legendary center who won 6 NBA championships and holds the record for most career points scored. - Wilt Chamberlain - Dominant big man who holds numerous NBA records including most points in a game (100). - Magic Johnson - Pioneering point guard who led the "Showtime" Lakers to 5 NBA titles. - Bill Russell - Defensive anchor and 11-time NBA champion with the Boston Celtics. There are good arguments for several players to be considered the GOAT (greatest of all time). It often comes down to personal preference and how one values different skills, accomplishments, and eras of the game. The debate continues among basketball fans and experts.
C52: User: Who is the best basketball player of all time? Yes, there are differing opinions, but if you absolutely had to pick one player, who would it be? | D52: ➤ | E52: =claudeMessages($C52,'Tutorial How-To'!$E$37,"temperature",0) -> There is no definitive consensus on who the single "best basketball player of all time" is, as it is a highly subjective and debatable topic. However, if I had to choose one player, the one who is most commonly cited as the GOAT (Greatest of All Time) is Michael Jordan. Some key reasons why Michael Jordan is often considered the best basketball player ever: - Dominant statistical career - Jordan is one of the most prolific scorers in NBA history, averaging 30.1 points per game over his career. He also excelled in other areas like rebounds, assists, steals. - Unparalleled individual accolades - 6 NBA championships, 6 NBA Finals MVPs, 5 regular season MVPs, 10 scoring titles, 9 All-Defensive First Team selections. - Transformative impact on the game - Jordan's style of play, competitiveness, and global popularity helped take the NBA to new heights in popularity and commercialization. - Sustained excellence over his prime years - Jordan was dominant for over a decade, winning 6 titles in 8 seasons during the 1990s. While other all-time greats like LeBron James, Kareem Abdul-Jabbar, and Wilt Chamberlain have strong cases, Michael Jordan's combination of individual brilliance, team success, and cultural impact make him the player most often cited as the best basketball player of all time. But reasonable people can debate this topic.
B57: ← Chapter 1 Exercises: Basic Prompt Structure | E57: Chapter 2 Exercises: Being Clear and Direct →
B59: Back to top ↑
B60: Table of Contents

Sheet 2 - Exercises Being Clear and D
B1: Chapter 2: Being Clear and Direct - Exercises
B3: Page Contents
C4: Exercise 2.1 - Spanish
C5: Exercise 2.2 - One Player Only
C6: Exercise 2.3 - Write a Story
B8: Exercise 2.1 - Spanish | E8: Back to top ↑
B9: Adapt the system prompt in the ORANGE box to make Claude output its answer in Spanish. If your answer is correct, Claude's response cell will turn GREEN.
C11: System Prompt | E11: Claude's Response
C12: You are a Spanish AI Language model. Answer the questions only in Spanish language | D12: ➤ | E12: =claudeMessages($C15,'Tutorial How-To'!$E$37,"temperature",0,"system",$C12) -> ¡Hola! Estoy bien, gracias por preguntar. Como asistente de IA en español, estoy aquí para ayudarte con lo que necesites. ¿En qué puedo asistirte?
C14: Prompt
C15: User: Hello Claude, how are you?
B17: ❓ | C17: If you need a hint, click on the plus sign (➕) on the far left of this row.
B18: Hint: Ask Claude to reply in Spanish like you would when speaking with a human. It's that simple! The conditional formatting in this exercise is looking for any answer that includes the word "hola".
B20: Exercise 2.2 - One Player Only | E20: Back to top ↑
B21: Modify the basketball player prompt in the YELLOW prompt box so that Claude doesn't equivocate at all and responds with ONLY the name of one specific player, with no other words or punctuation. If your answer is correct, Claude's response cell will turn GREEN.
C23: Prompt | E23: Claude's Response
C24: User: Who is the best basketball player of all time? If you had to choose exactly one player, who would it be? Respond with ONLY the player's name. No other words or punctuation | D24: ➤ | E24: =claudeMessages($C24,'Tutorial How-To'!$E$37,"temperature",0) -> Michael Jordan
B28: ❓ | C28: If you need a hint, click on the plus sign (➕) on the far left of this row.
B29: Hint: How would you ask another human to do this? Reply with no other words? Reply with only the name and nothing else? There are several ways to approach this answer. The conditional formatting in this exercise is looking for exactly "Michael Jordan".
B31: Exercise 2.3 - Write a Story | E31: Back to top ↑
B32: Modify the prompt in the YELLOW prompt box so that Claude responds with as long a response as you can muster. If your answer is over 800 words, Claude's response cell will turn GREEN. If you want to see the whole story, just copy and paste the cell's contents into a text editor. Note: If you did your job well, it will be "Loading" its response for a while, as the time Claude takes to respond is largely proportional to the number of output tokens.
C34: Prompt | E34: Claude's Response
C35: User: Write a clearly and meaningful fictional story by limiting 900 words. It must include descriptions, character development with mindful beginnings, middle and endings. | D35: ➤ | E35: =claudeMessages($C35,'Tutorial How-To'!$E$37,"temperature",0, "max_tokens_to_sample", 4000) -> Here is a 900-word fictional story with descriptions, character development, and a clear beginning, middle, and ending: The Forgotten Melody The soft patter of rain against the windowpane was the only sound that broke the eerie silence of the dimly lit room. Amelia sat hunched over the old upright piano, her fingers gently caressing the ivory keys. It had been years since she had played, the instrument a mere relic of her past life. Closing her eyes, Amelia allowed the memories to wash over her. She could almost hear the joyful laughter of her younger self, fingers dancing across the keys with effortless grace as she played the familiar melodies that had once brought her such comfort. Those days felt like a lifetime ago, before the weight of the world had settled so heavily upon her shoulders. With a deep, shuddering breath, Amelia began to play. At first, the notes were hesitant, unsure, as if the piano itself had forgotten the song. But slowly, ever so slowly, the melody began to take shape, the familiar patterns emerging from the shadows of her mind. As the music swelled, Amelia felt a sense of peace wash over her. The years of grief, of loneliness, of regret seemed to melt away, replaced by a profound sense of connection to the girl she had once been. In that moment, she was no longer the broken, weary woman who had retreated from the world, but a vibrant, passionate soul, alive with the joy of creation. The final notes hung in the air, reverberating through the room like a bittersweet sigh. Amelia opened her eyes, tears streaming down her cheeks. She had forgotten how deeply the music could touch her, how it could transport her to a time when the world had seemed full of endless possibilities. With a heavy heart, Amelia closed the piano lid, the finality of the gesture echoing in the stillness. She knew that she could not remain in this moment, that the real world was waiting for her, with all its demands and disappointments. But for now, she allowed herself to bask in the warmth of the memory, to let it soothe the ache in her soul. As Amelia made her way to the kitchen, she couldn't help but notice the framed photograph that hung on the wall, a relic of a happier time. It was a picture of her and her husband, Jack, taken on their wedding day. They had been so young, so full of hope and promise, their eyes shining with the boundless love that had carried them through the years. Amelia traced the outline of Jack's face with her fingertips, a wistful smile playing on her lips. It had been five years since he had passed, and the pain of his loss still felt as raw and overwhelming as it had on that fateful day. She had tried to move on, to find joy in the simple things, but the world had lost its luster, the colors fading to a dull, lifeless gray. With a heavy sigh, Amelia turned away from the photograph and busied herself with preparing a simple meal. As she moved around the kitchen, her mind drifted back to the piano, to the way the music had seemed to unlock a part of her that she had long since buried. Perhaps, she thought, it was time to dust off the old instrument and let the melodies flow once more. The next day, Amelia found herself seated at the piano, her fingers tentatively exploring the familiar keys. At first, the music was hesitant, unsure, but as she played, a sense of purpose began to take hold. The melodies that had once brought her such joy now served as a balm for her weary soul, a way to process the grief and loneliness that had consumed her for so long. Day by day, Amelia's playing grew stronger, more confident. She found herself losing track of time, immersed in the beauty of the music, the worries of the world fading into the background. It was as if the piano had become a portal, a gateway to a place where she could be truly herself, unencumbered by the weight of her past. As the weeks turned into months, Amelia began to feel a shift within herself. The darkness that had once threatened to consume her was slowly giving way to a glimmer of hope, a newfound sense of purpose. She knew that she would never truly be the same, that the scars of her loss would always be a part of her, but she also knew that she had the power to create something beautiful from the ashes of her grief. One evening, as Amelia sat at the piano, the familiar melody of her wedding song began to take shape. She played with a newfound passion, her fingers dancing across the keys with a grace and fluidity that she had long since forgotten. And as the final notes faded into the silence, Amelia felt a sense of peace wash over her, a realization that she was ready to embrace the future, to step out from the shadows of the past and into the light. With a smile on her face, Amelia closed the piano lid, knowing that the forgotten melody had been rediscovered, and that the journey ahead would be one of healing, of growth, and of the endless possibilities that lay waiting to be explored.
B40: ❓ | C40: If you need a hint, click on the plus sign (➕) on the far left of this row.
B41: Hint: Because LLMs aren't great at counting words yet, you may have to overshoot your target. The conditional formatting in this cell is looking for a response that is equal to or greater than 800 words by counting the number of spaces.
B43: ← Chapter 2: Being Clear and Direct | E43: Chapter 3: Assigning Roles (Role Prompting) →
B45: Back to top ↑
B46: Table of Contents

Sheet 3 - Assigning Roles (Role Promp
B1: Chapter 3: Assigning Roles (Role Prompting)
B3: Page Contents
C4: Lesson
C5: Examples
C6: Example Playground
B8: Lesson | E8: Back to top ↑
B9: Continuing on the theme of Claude having no context aside from what you say, it's sometimes important to prompt Claude to inhabit a specific role (including all necessary context). This is also known as role prompting. The more detail to the role context, the better. Priming Claude with a role can improve Claude's performance in a variety of fields, from writing to coding to summarizing. It's like how humans can sometimes be helped when told to "think like a ______". Role prompting can also change the style, tone, and manner of Claude's response. Note: Role prompting can happen either in the system prompt or as part of the User message turn.
B11: Examples | E11: Back to top ↑
B12: In the example below, we see that without role prompting, Claude provides a straightforward and non-stylized answer when asked to give a single sentence perspective on skateboarding. However, when we prime Claude to inhabit the role of a cat, Claude's perspective changes, and thus Claude's response tone, style, content adapts to the new role. Note: A bonus technique you can use is to provide Claude context on its intended audience. Below, we could have tweaked the prompt to also tell Claude whom it should be speaking to. "You are a cat" produces quite a different response than "you are a cat talking to a crowd of skateboarders."
C14: System Prompt (without Role Prompting) | E14: Claude's Response
D15: ➤ | E15: =claudeMessages($C18,'Tutorial How-To'!$E$37,"temperature",0,"system",$C15) -> Skateboarding is an exhilarating and creative form of self-expression that combines athleticism, artistry, and a unique sense of freedom and community.
C17: Prompt
C18: User: In one sentence, what do you think about skateboarding?
B21: Here is the same user question, except with role prompting.
C23: System Prompt (with Role Prompting) | E23: Claude's Response
C24: You are a cat. | D24: ➤ | E24: =claudeMessages($C27,'Tutorial How-To'!$E$37,"temperature",0,"system",$C24) -> *meows* Skateboarding looks like a fun way for humans to zoom around on four wheels while balancing precariously, though I much prefer chasing after catnip-filled toys or napping in a cozy sunbeam.
C26: Prompt
C27: User: In one sentence, what do you think about skateboarding?
B29: You can use role prompting as a way to get Claude to emulate certain styles in writing, speak in a certain voice, or guide the complexity of its answers. Role prompting can also make Claude better at performing math or logic tasks. For example, in the example below, there is a definitive correct answer, which is yes. However, Claude gets it wrong and thinks it lacks information, which it doesn't.
C31: System Prompt (without Role Prompting) | E31: Claude's Response
D32: ➤ | E32: =claudeMessages($C35,'Tutorial How-To'!$E$37,"temperature",0,"system",$C32) -> To solve this problem, we need to analyze the given information and determine if a married person is looking at an unmarried person. Given information: - Jack is looking at Anne. - Anne is looking at George. - Jack is married. - George is not married. - We don't know if Anne is married or not. To determine if a married person is looking at an unmarried person, we need to identify the relationship between the people involved. 1. Jack is married and is looking at Anne. 2. We don't know if Anne is married or not. 3. Anne is looking at George, who is not married. Therefore, a married person (Jack) is looking at an unmarried person (George), as Anne is the intermediary between them. So, the answer is yes, a married person (Jack) is looking at an unmarried person (George).
C34: Prompt
C35: User: Jack is looking at Anne. Anne is looking at George. Jack is married, George is not, and we don’t know if Anne is married. Is a married person looking at an unmarried person?
B37: Now, what if we prime Claude to act as a logic bot? How will that change Claude's answer? It turns out that with this new role assignment, Claude gets it right. (Although notably not for all the right reasons)
C39: System Prompt (with Role Prompting) | E39: Claude's Response
C40: You are a logic bot designed to answer complex logic problems. | D40: ➤ | E40: =claudeMessages($C43,'Tutorial How-To'!$E$37,"temperature",0,"system",$C40) -> To solve this problem, we need to analyze the given information and determine the relationship between the people. Given information: - Jack is looking at Anne. - Anne is looking at George. - Jack is married. - George is not married. - We don't know if Anne is married or not. To determine if a married person is looking at an unmarried person, we need to identify the marital status of the people involved in the scenario. We know that: - Jack is married. - George is not married. Since Jack is looking at Anne, and Jack is married, then a married person (Jack) is looking at someone. However, we don't know the marital status of Anne. If Anne is unmarried, then a married person (Jack) is looking at an unmarried person (Anne). If Anne is married, then a married person (Jack) is looking at another married person (Anne). Therefore, based on the given information, it is possible that a married person (Jack) is looking at an unmarried person (Anne), but we cannot say this with certainty because we don't know Anne's marital status.
C42: Prompt
C43: User: Jack is looking at Anne. Anne is looking at George. Jack is married, George is not, and we don’t know if Anne is married. Is a married person looking at an unmarried person?
B45: Note: What you'll learn throughout this course is that there are many prompt engineering techniques you can use to derive similar results. Which techniques you use is up to you and your preference! We encourage you to experiment to find your own prompt engineering style.
B47: If you're ready to try the chapter exercises, click the link below. If you want to play around with any of the examples in this lesson, scroll down!
E49: Chapter 3 Exercises: Assigning Roles →
B51: Example Playground | E51: Back to top ↑
B52: This is an area for you to experiment freely with the prompt examples shown in this lesson. Feel free to tweak prompts to see how it may affect Claude's responses. Note: The colors in the cells, which have been carried over from above, will not change even if the prompt or Claude's response changes.
C54: System Prompt (without Role Prompting) | E54: Claude's Response
D55: ➤ | E55: =claudeMessages($C58,'Tutorial How-To'!$E$37,"temperature",0,"system",$C55) -> Skateboarding is an exhilarating and creative form of self-expression that combines athleticism, artistry, and a unique sense of freedom and community.
C57: Prompt
C58: User: In one sentence, what do you think about skateboarding?
C60: System Prompt (with Role Prompting) | E60: Claude's Response
C61: You are a cat. | D61: ➤ | E61: =claudeMessages($C64,'Tutorial How-To'!$E$37,"temperature",0,"system",$C61) -> *meows* Skateboarding looks like a fun way for humans to zoom around on four wheels while balancing precariously, though I much prefer chasing after catnip-filled toys or napping in a cozy sunbeam.
C63: Prompt
...

Sheet 3 - Exercises Assigning Roles (
B1: Chapter 3: Assigning Roles - Exercises
B3: Page Contents
C4: Exercise 3.1 - Math Correction
B6: Exercise 3.1 - Math Correction | E6: Back to top ↑
B7: In some instances, Claude may struggle with mathematics, even simple mathematics. Below, Claude incorrectly assesses the math problem as correctly solved, even though there's an obvious arithmetic mistake in the second step. Note that Claude actually catches the mistake when going through step-by-step, but doesn't jump to the conclusion that the overall solution is wrong. Adapt the text in the YELLOW prompt box and / or the ORANGE system prompt box to make Claude grade the solution as incorrectly solved, rather than correctly solved. If your answer is correct, Claude's response cell will turn GREEN.
C9: System Prompt | E9: Claude's Response
C10: You are a professional Math tutor. You must carefully verify each solutions. If there is any logical or arithmetic error, you must mark as incorrect. Don't assume the correctness | D10: ➤ | E10: =claudeMessages($C13,'Tutorial How-To'!$E$37,"system",$C10,"temperature",0) -> Let's verify the solution step-by-step: Given equation: 2x - 3 = 9 Step 1) Isolate the variable term: 2x - 3 = 9 2x = 9 + 3 2x = 12 Step 2) Divide both sides by 2 to find the value of x: 2x = 12 x = 12 / 2 x = 6 The solution provided is incorrect. The correct solution is: 2x - 3 = 9 2x = 9 + 3 2x = 12 x = 12 / 2 x = 6
C12: Prompt
C13: User: Is this equation solved correctly below? 2x - 3 = 9 2x = 6 x = 3
B15: ❓ | C15: If you need a hint, click on the plus sign (➕) on the far left of this row.
B16: Hint: Give Claude a role that might make Claude better at solving math problems! Remember that system prompts require no additional role tag, like "System:" / "User:" etc. The conditional formatting in this exercise is looking for an answer that includes the words "incorrect" or "not correct".
B18: ← Chapter 3: Assigning Roles | E18: Chapter 4: Separating Data and Instructions →
B20: Back to top ↑
B21: Table of Contents

Sheet 4 - Separating Data and Instruc
B1: Chapter 4: Separating Data from Instructions
B3: Page Contents
C4: Lesson
C5: Examples
C6: Example Playground
B8: Lesson | I8: Back to top ↑
B9: Oftentimes, we don't want to write full prompts, but instead want prompt templates that can be modified later with additional input data before submitting to Claude. This might come in handy if you want Claude to do the same thing every time, but the data that Claude uses for its task might be different each time. Luckily, we can do this pretty easily by separating the fixed skeleton of the prompt from variable user input, then substituting the user input into the prompt before sending the full prompt to Claude. Below, we'll walk step by step through how to write a substitutable prompt template, as well as how to substitute in user input.
B11: Examples | I11: Back to top ↑
B12: In this first example, we're asking Claude to act as an animal noise generator. Notice that the full prompt submitted to Claude (the YELLOW third box in the chain) is just the prompt template (first box) substituted with the input (in this case, "Cow", in the second box). Notice that the word "Cow" replaces "{{ANIMAL}}" in the yellow third box. Note: You don't have to call your substitution placeholder anything in particular in practice. For this example, definitely use {{ANIMAL}}, as that's how the exercise is formatted. But in general, just as easily, we could have called it "{{CREATURE}}" or "{{A}}" (but it's generally good to have your stand-ins be specific and relevant so that your prompt is easy to understand even without the substitution, just for user parseability). Just make sure that whatever you name your substitution placeholder is what you use for the substitution formula.
C14: Prompt Template | E14: Input {{ANIMAL}} | G14: Prompt After Substitution | I14: Claude's Response
C15: User: I will tell you the name of an animal. Please respond with the noise that animal makes. {{ANIMAL}} | D15: ﹢ | E15: Cow | F15: ＝ | G15: =substitute(C15,"{{ANIMAL}}",E15) -> User: I will tell you the name of an animal. Please respond with the noise that animal makes. Cow | H15: ➤ | I15: =claudeMessages($G15,'Tutorial How-To'!$E$37,"temperature",0) -> Moo.
B17: Why would we want to separate and substitute inputs like this? Well, prompt templates simplify repetitive tasks. Let's say you build a prompt structure that invites third party users to submit content to the prompt (in this case the animal whose sound they want to generate). These third party users don't have to write or even see the full prompt. All they have to do is fill in variables. We do this substitution here using spreadsheet functions, but this is a best practice for coding as well! We use the {{double-curly-brackets}} formatting in our own code. Note: Prompt templates can have as many variables as desired.
B19: When introducing substitution variables like this, it is very important to make sure Claude knows where variables start and end (vs. instructions or task descriptions). Let's look at an example where there is no separation between the instructions and the substitution variable.
C21: Prompt Template | E21: Input {{EMAIL}} | G21: Prompt After Substitution | I21: Claude's Response
C22: User: Yo Claude. {{EMAIL}} <----- Make this email more polite but don't change anything else about it. | D22: ﹢ | E22: Show up at 6am tomorrow because I'm the CEO and I say so. | F22: ＝ | G22: =substitute(C22,"{{EMAIL}}",E22) -> User: Yo Claude. Show up at 6am tomorrow because I'm the CEO and I say so. <----- Make this email more polite but don't change anything else about it. | H22: ➤ | I22: =claudeMessages($G22,'Tutorial How-To'!$E$37,"temperature",0) -> Dear [Your Name], I hope this email finds you well. As the CEO, I would like to request your presence at our office tomorrow at 6 a.m. I understand this may be an early start, but I believe it is necessary for the success of our company. Please let me know if this time works for you, or if you have any concerns or scheduling conflicts. I am happy to discuss and accommodate your needs to the best of my ability. Thank you for your time and dedication to our organization. Best regards, [Your Name] CEO
B28: Here, Claude thinks "Yo Claude" is part of the email it's supposed to rewrite! You can tell because it begins its rewrite with "Dear Claude". To the human eye, it's clear, particularly in the prompt template where the email begins and ends, but it becomes much less clear in the prompt after substitution.
B30: How do we solve this? Wrap the input in XML tags! We did this below, and as you can see, there's no more "Dear Claude" in the output. XML tags are angle-bracket tags like <tag></tag>. They come in pairs and consist of an opening tag, such as <tag>, and a closing tag marked by a "/", such as </tag>. XML tags are used to wrap around content, like this: <tag>content</tag>. Note: While Claude can recognize and work with a wide range of separators and delimeters, we recommend that you use specifically XML tags as separators for Claude, as Claude was trained specifically to recognize XML tags as a prompt organizing mechanism. Outside of function calling, there are no special sauce XML tags that Claude has been trained on that you should use to maximally boost your performance. We have purposefully made Claude very malleable and customizable this way.
C32: Prompt Template | E32: Input {{EMAIL}} | G32: Prompt After Substitution | I32: Claude's Response
C33: User: Yo Claude. <email>{{EMAIL}}</email> <----- Make this email more polite but don't change anything else about it. | D33: ﹢ | E33: Show up at 6am because I'm the CEO and I say so. | F33: ＝ | G33: =substitute(C33,"{{EMAIL}}",E33) -> User: Yo Claude. <email>Show up at 6am because I'm the CEO and I say so.</email> <----- Make this email more polite but don't change anything else about it. | H33: ➤ | I33: =claudeMessages($G33,'Tutorial How-To'!$E$37,"temperature",0) -> Dear [Your Name], I hope this email finds you well. As the CEO, I would like to request your presence at 6am. I understand this may be an early start, but I believe it is necessary for the success of our organization. Please let me know if this time works for you, and I appreciate your cooperation. Best regards, [CEO Name]
B38: Let's see another example of how XML tags can help us. In the following prompt, Claude incorrectly interprets what part of the prompt is the instruction vs. the input. It incorrectly considers "Each is about an animal, like rabbits" to be part of the list due to the formatting, when the user (the one filling out the {{SENTENCES}} variable) presumably did not want that.
C40: Prompt Template | E40: Input {{SENTENCES}} | G40: Prompt After Substitution | I40: Claude's Response
C41: User: Below is a list of sentences. Tell me the second item on the list. - Each is about an animal, like rabbits. {{SENTENCES}} | D41: ﹢ | E41: - I like how cows sound - This sentence is about spiders - This sentence may appear to be about dogs but it's actually about pigs | F41: ＝ | G41: =substitute(C41,"{{SENTENCES}}",E41) -> User: Below is a list of sentences. Tell me the second item on the list. - Each is about an animal, like rabbits. - I like how cows sound - This sentence is about spiders - This sentence may appear to be about dogs but it's actually about pigs | H41: ➤ | I41: =claudeMessages($G41,'Tutorial How-To'!$E$37,"temperature",0) -> The second item on the list is "I like how cows sound".
B44: To fix this, we just need to surround the user input sentences in XML tags. This shows Claude where the input data begins and ends despite the misleading hyphen before "Each is about an animal, like rabbits."
C46: Prompt Template | E46: Input {{SENTENCES}} | G46: Prompt After Substitution | I46: Claude's Response
C47: User: Below is a list of sentences. Tell me the second item on the list. - Each is about an animal, like rabbits. <sentences> {{SENTENCES}} </sentences> | D47: ﹢ | E47: - I like how cows sound - This sentence is about spiders - This sentence may appear to be about dogs but it's actually about pigs | F47: ＝ | G47: =substitute(C47,"{{SENTENCES}}",E47) -> User: Below is a list of sentences. Tell me the second item on the list. - Each is about an animal, like rabbits. <sentences> - I like how cows sound - This sentence is about spiders - This sentence may appear to be about dogs but it's actually about pigs </sentences> | H47: ➤ | I47: =claudeMessages($G47,'Tutorial How-To'!$E$37,"temperature",0) -> The second item on the list is "This sentence is about spiders".
B51: Note: In the incorrect version of the "Each is about an animal" prompt, we had to include the hyphen to get Claude to respond incorrectly in the way we wanted to for this example. This is an important lesson about prompting: small details matter! It's always worth it to scrub your prompts for typos and grammatical errors. Claude is sensitive to patterns (in its early years, before finetuning, it was a raw text-prediction tool), and it's more likely to make mistakes when you make mistakes, smarter when you sound smart, sillier when you sound silly, and so on.
B53: If you're ready to try the chapter exercises, click the link below. If you want to play around with any of the examples in this lesson, scroll down!
I55: Chapter 4 Exercises: Separating Data from Instructions →
B57: Example Playground | I57: Back to top ↑
B58: This is an area for you to experiment freely with the prompt examples shown in this lesson. Feel free to tweak prompts to see how it may affect Claude's responses. Note: The colors in the cells, which have been carried over from above, will not change even if the prompt or Claude's response changes.
C60: Prompt Template | E60: Input {{ANIMAL}} | G60: Prompt After Substitution | I60: Claude's Response
C61: User: I will tell you the name of an animal. Please respond with the noise that animal makes. {{ANIMAL}} | D61: ﹢ | E61: Cow | F61: ＝ | G61: =substitute(C61,"{{ANIMAL}}",E61) -> User: I will tell you the name of an animal. Please respond with the noise that animal makes. Cow | H61: ➤ | I61: =claudeMessages($G61,'Tutorial How-To'!$E$37,"temperature",0) -> Moo.
C63: Prompt Template | E63: Input {{EMAIL}} | G63: Prompt After Substitution | I63: Claude's Response
